TemplateNotFound
jinja2.exceptions.TemplateNotFound: settings.html

Traceback (most recent call last)
File "/home/runner/workspace/.pythonlibs/lib/python3.11/site-packages/pyttsx3/__init__.py", line 22, in init
eng = _activeEngines[driverName]
      ^^^^^^^^^^^^^^^^^^^^^^^^^^
File "/nix/store/7d088dip86hlzri9sk0h78b63yfmx0a0-python3-3.11.13/lib/python3.11/weakref.py", line 136, in __getitem__
o = self.data[key]()
    ^^^^^^^^^^^^^^
During handling of the above exception, another exception occurred:
File "/home/runner/workspace/routes/main_routes.py", line 36, in settings
from services.voice_service import voice_service
^^^^^^^^^^^^^^^^^^^^^^^^^^^^^^^^^^^^^^^^^^^^^^^^
File "/home/runner/workspace/services/voice_service.py", line 76, in <module>
voice_service = VoiceService()
                ^^^^^^^^^^^^^^
File "/home/runner/workspace/services/voice_service.py", line 7, in __init__
self.engine = pyttsx3.init()
              ^^^^^^^^^^^^^^
File "/home/runner/workspace/.pythonlibs/lib/python3.11/site-packages/pyttsx3/__init__.py", line 24, in init
eng = Engine(driverName, debug)
      ^^^^^^^^^^^^^^^^^^^^^^^^^
File "/home/runner/workspace/.pythonlibs/lib/python3.11/site-packages/pyttsx3/engine.py", line 59, in __init__
self.proxy = driver.DriverProxy(weakref.proxy(self), self.driver_name, debug)
             ^^^^^^^^^^^^^^^^^^^^^^^^^^^^^^^^^^^^^^^^^^^^^^^^^^^^^^^^^^^^^^^^
File "/home/runner/workspace/.pythonlibs/lib/python3.11/site-packages/pyttsx3/driver.py", line 41, in __init__
self._module = importlib.import_module(f"pyttsx3.drivers.{driverName}")
               ^^^^^^^^^^^^^^^^^^^^^^^^^^^^^^^^^^^^^^^^^^^^^^^^^^^^^^^^
File "/nix/store/7d088dip86hlzri9sk0h78b63yfmx0a0-python3-3.11.13/lib/python3.11/importlib/__init__.py", line 126, in import_module
return _bootstrap._gcd_import(name[level:], package, level)
       ^^^^^^^^^^^^^^^^^^^^^^^^^^^^^^^^^^^^^^^^^^^^^^^^^^^^
File "/home/runner/workspace/.pythonlibs/lib/python3.11/site-packages/pyttsx3/drivers/espeak.py", line 15, in <module>
from . import _espeak
File "/home/runner/workspace/.pythonlibs/lib/python3.11/site-packages/pyttsx3/drivers/_espeak.py", line 61, in <module>
raise RuntimeError(msg)
^^^^^^^^^^^^^^^^^^^^^^^
During handling of the above exception, another exception occurred:
File "/home/runner/workspace/.pythonlibs/lib/python3.11/site-packages/flask/app.py", line 1536, in __call__
return self.wsgi_app(environ, start_response)
       ^^^^^^^^^^^^^^^^^^^^^^^^^^^^^^^^^^^^^^
File "/home/runner/workspace/.pythonlibs/lib/python3.11/site-packages/werkzeug/middleware/proxy_fix.py", line 183, in __call__
return self.app(environ, start_response)
       ^^^^^^^^^^^^^^^^^^^^^^^^^^^^^^^^^
File "/home/runner/workspace/.pythonlibs/lib/python3.11/site-packages/flask/app.py", line 1514, in wsgi_app
response = self.handle_exception(e)
           ^^^^^^^^^^^^^^^^^^^^^^^^
File "/home/runner/workspace/.pythonlibs/lib/python3.11/site-packages/flask/app.py", line 1511, in wsgi_app
response = self.full_dispatch_request()
           ^^^^^^^^^^^^^^^^^^^^^^^^^^^^
File "/home/runner/workspace/.pythonlibs/lib/python3.11/site-packages/flask/app.py", line 919, in full_dispatch_request
rv = self.handle_user_exception(e)
     ^^^^^^^^^^^^^^^^^^^^^^^^^^^^^
File "/home/runner/workspace/.pythonlibs/lib/python3.11/site-packages/flask/app.py", line 917, in full_dispatch_request
rv = self.dispatch_request()
     ^^^^^^^^^^^^^^^^^^^^^^^
File "/home/runner/workspace/.pythonlibs/lib/python3.11/site-packages/flask/app.py", line 902, in dispatch_request
return self.ensure_sync(self.view_functions[rule.endpoint])(**view_args)  # type: ignore[no-any-return]
       ^^^^^^^^^^^^^^^^^^^^^^^^^^^^^^^^^^^^^^^^^^^^^^^^^^^^^^^^^^^^^^^^^
File "/home/runner/workspace/routes/main_routes.py", line 42, in settings
return render_template('settings.html', voice_info={}, error="Error loading settings")
       ^^^^^^^^^^^^^^^^^^^^^^^^^^^^^^^^^^^^^^^^^^^^^^^^^^^^^^^^^^^^^^^^^^^^^^^^^^^^^^^
File "/home/runner/workspace/.pythonlibs/lib/python3.11/site-packages/flask/templating.py", line 149, in render_template
template = app.jinja_env.get_or_select_template(template_name_or_list)
           ^^^^^^^^^^^^^^^^^^^^^^^^^^^^^^^^^^^^^^^^^^^^^^^^^^^^^^^^^^^
File "/home/runner/workspace/.pythonlibs/lib/python3.11/site-packages/jinja2/environment.py", line 1087, in get_or_select_template
return self.get_template(template_name_or_list, parent, globals)
       ^^^^^^^^^^^^^^^^^^^^^^^^^^^^^^^^^^^^^^^^^^^^^^^^^^^^^^^^^
File "/home/runner/workspace/.pythonlibs/lib/python3.11/site-packages/jinja2/environment.py", line 1016, in get_template
return self._load_template(name, globals)
       ^^^^^^^^^^^^^^^^^^^^^^^^^^^^^^^^^^
File "/home/runner/workspace/.pythonlibs/lib/python3.11/site-packages/jinja2/environment.py", line 975, in _load_template
template = self.loader.load(self, name, self.make_globals(globals))
           ^^^^^^^^^^^^^^^^^^^^^^^^^^^^^^^^^^^^^^^^^^^^^^^^^^^^^^^^
File "/home/runner/workspace/.pythonlibs/lib/python3.11/site-packages/jinja2/loaders.py", line 126, in load
source, filename, uptodate = self.get_source(environment, name)
                             ^^^^^^^^^^^^^^^^^^^^^^^^^^^^^^^^^^
File "/home/runner/workspace/.pythonlibs/lib/python3.11/site-packages/flask/templating.py", line 65, in get_source
return self._get_source_fast(environment, template)
       ^^^^^^^^^^^^^^^^^^^^^^^^^^^^^^^^^^^^^^^^^^^^
File "/home/runner/workspace/.pythonlibs/lib/python3.11/site-packages/flask/templating.py", line 99, in _get_source_fast
raise TemplateNotFound(template)
^^^^^^^^^^^^^^^^^^^^^^^^^^^^^^^^
jinja2.exceptions.TemplateNotFound: settings.html
The debugger caught an exception in your WSGI application. You can now look at the traceback which led to the error.
To switch between the interactive traceback and the plaintext one, you can click on the "Traceback" headline. From the text traceback you can also create a paste of it.

